#ValueErrorに対処する例外処理の例
#try-except-else-finally文の使用
#try:
#    pin = int(input("pinを入力してください: "))
#except valueerror:
#    print("数値だけ入力してください")
#else: 
#    print("あなたの入力:", pin)
#finally:
#    print("もう終わりましたか？")
#一行目はエラーがでない。assertの条件式がTrueになるから。二行目はFalseになりAssertionErrorを吐く
assert 1 + 1 == 2
assert 2 + 2 == 5
